{-# LANGUAGE CPP #-}
{-# LANGUAGE DeriveDataTypeable #-}
{-# LANGUAGE ExistentialQuantification #-}
{-# LANGUAGE ScopedTypeVariables #-}
-- | Please see the README.md file in the safe-exceptions repo for
-- information on how to use this module. Relevant links:
--
-- * https://github.com/fpco/safe-exceptions#readme
--
-- * https://www.stackage.org/package/safe-exceptions
module Control.Exception.Safe
    ( -- * Throwing
      throw
    , throwIO
    , throwM
    , throwTo
    , impureThrow
      -- * Catching (with recovery)
    , catch
    , catchAny
    , catchAsync

    , handle
    , handleAny
    , handleAsync

    , try
    , tryAny
    , tryAsync

      -- * Cleanup (no recovery)
    , onException
    , bracket
    , bracket_
    , finally
    , withException
    , bracketOnError
    , bracketOnError_

      -- * Coercion to sync and async
    , SyncExceptionWrapper (..)
    , toSyncException
    , AsyncExceptionWrapper (..)
    , toAsyncException

      -- * Check exception type
    , isSyncException
    , isAsyncException
      -- * Reexports
    , C.MonadThrow
    , C.MonadCatch
    , C.MonadMask (..)
    , C.mask_
    , C.uninterruptibleMask_
    , C.catchIOError
    , C.handleIOError
    -- FIXME , C.tryIOError
    , C.Handler (..)
    , Exception (..)
    , SomeException (..)
    , SomeAsyncException (..)
    , E.IOException
#if !MIN_VERSION_base(4,8,0)
    , displayException
#endif
    ) where

import Control.Concurrent (ThreadId)
import Control.Exception (Exception (..), SomeException (..), SomeAsyncException (..))
import qualified Control.Exception as E
import qualified Control.Monad.Catch as C
import Control.Monad (liftM)
import Control.Monad.IO.Class (MonadIO, liftIO)
import Data.Typeable (Typeable, cast)

-- | Synchronously throw the given exception
--
-- @since 0.1.0.0
throw :: (C.MonadThrow m, Exception e) => e -> m a
throw = C.throwM . toSyncException

-- | Synonym for 'throw'
--
-- @since 0.1.0.0
throwIO :: (C.MonadThrow m, Exception e) => e -> m a
throwIO = throw

-- | Synonym for 'throw'
--
-- @since 0.1.0.0
throwM :: (C.MonadThrow m, Exception e) => e -> m a
throwM = throw

-- | Throw an asynchronous exception to another thread
--
-- It's usually a better idea to use the async package, see
-- <https://github.com/fpco/safe-exceptions#quickstart>
--
-- @since 0.1.0.0
throwTo :: (Exception e, MonadIO m) => ThreadId -> e -> m ()
throwTo tid = liftIO . E.throwTo tid . toAsyncException

-- | Generate a pure value which, when forced, will synchronously
-- throw the given exception
--
-- Generally it's better to avoid using this function and instead use 'throw',
-- see <https://github.com/fpco/safe-exceptions#quickstart>
--
-- @since 0.1.0.0
impureThrow :: Exception e => e -> a
impureThrow = E.throw . toSyncException

-- | Catch an exception and run a recovery step
--
-- @since 0.1.0.0
catch :: (C.MonadCatch m, Exception e) => m a -> (e -> m a) -> m a
catch f g = f `C.catch` \e ->
    if isSyncException e
        then g e
        -- intentionally rethrowing an async exception synchronously,
        -- since we want to preserve async behavior
        else C.throwM e

-- | 'catch' specialized to catch all synchronous exception
--
-- @since 0.1.0.0
catchAny :: C.MonadCatch m => m a -> (SomeException -> m a) -> m a
catchAny = catch

-- | 'catch' without async exception safety
--
-- Generally it's better to avoid using this function since we do not want to
-- recover from async exceptions, see
-- <https://github.com/fpco/safe-exceptions#quickstart>
--
-- @since 0.1.0.0
catchAsync :: (C.MonadCatch m, Exception e) => m a -> (e -> m a) -> m a
catchAsync = C.catch

-- | Flipped version of 'catch'
--
-- @since 0.1.0.0
handle :: (C.MonadCatch m, Exception e) => (e -> m a) -> m a -> m a
handle = flip catch

-- | Flipped version of 'catchAny'
--
-- @since 0.1.0.0
handleAny :: C.MonadCatch m => (SomeException -> m a) -> m a -> m a
handleAny = flip catchAny

-- | Flipped version of 'catchAsync'
--
-- Generally it's better to avoid using this function since we do not want to
-- recover from async exceptions, see
-- <https://github.com/fpco/safe-exceptions#quickstart>
--
-- @since 0.1.0.0
handleAsync :: (C.MonadCatch m, Exception e) => (e -> m a) -> m a -> m a
handleAsync = C.handle

-- | Same as upstream 'C.try', but will not catch asynchronous
-- exceptions
--
-- @since 0.1.0.0
try :: (C.MonadCatch m, E.Exception e) => m a -> m (Either e a)
try f = catch (liftM Right f) (return . Left)

-- | 'try' specialized to catch all synchronous exceptions
--
-- @since 0.1.0.0
tryAny :: C.MonadCatch m => m a -> m (Either SomeException a)
tryAny = try

-- | 'try' without async exception safety
--
-- Generally it's better to avoid using this function since we do not want to
-- recover from async exceptions, see
-- <https://github.com/fpco/safe-exceptions#quickstart>
--
-- @since 0.1.0.0
tryAsync :: (C.MonadCatch m, E.Exception e) => m a -> m (Either e a)
tryAsync = C.try

-- | Async safe version of 'E.onException'
--
-- @since 0.1.0.0
onException :: C.MonadMask m => m a -> m b -> m a
onException thing after = withException thing (\(_ :: SomeException) -> after)

-- | Like 'onException', but provides the handler the thrown
-- exception.
--
-- @since 0.1.0.0
withException :: (C.MonadMask m, E.Exception e) => m a -> (e -> m b) -> m a
withException thing after = C.uninterruptibleMask $ \restore -> do
    res1 <- C.try $ restore thing
    case res1 of
        Left e1 -> do
            -- see explanation in bracket
            _ :: Either SomeException b <- C.try $ after e1
            C.throwM e1
        Right x -> return x

-- | Async safe version of 'E.bracket'
--
-- @since 0.1.0.0
bracket :: forall m a b c. C.MonadMask m
        => m a -> (a -> m b) -> (a -> m c) -> m c
bracket before after thing = C.mask $ \restore -> do
    x <- before
    res1 <- C.try $ restore (thing x)
    case res1 of
        Left (e1 :: SomeException) -> do
            -- explicitly ignore exceptions from after. We know that
            -- no async exceptions were thrown there, so therefore
            -- the stronger exception must come from thing
            --
            -- https://github.com/fpco/safe-exceptions/issues/2
            _ :: Either SomeException b <-
                C.try $ C.uninterruptibleMask_ $ after x
            C.throwM e1
        Right y -> do
            C.uninterruptibleMask_ $ after x
            return y

-- | Async safe version of 'E.bracket_'
--
-- @since 0.1.0.0
bracket_ :: C.MonadMask m => m a -> m b -> m c -> m c
bracket_ before after thing = bracket before (const after) (const thing)

-- | Async safe version of 'E.finally'
--
-- @since 0.1.0.0
finally :: C.MonadMask m => m a -> m b -> m a
finally thing after = C.uninterruptibleMask $ \restore -> do
    res1 <- C.try $ restore thing
    case res1 of
        Left (e1 :: SomeException) -> do
            -- see bracket for explanation
            _ :: Either SomeException b <- C.try after
            C.throwM e1
        Right x -> do
            after
            return x

-- | Async safe version of 'E.bracketOnError'
--
-- @since 0.1.0.0
bracketOnError :: forall m a b c. C.MonadMask m
               => m a -> (a -> m b) -> (a -> m c) -> m c
bracketOnError before after thing = C.mask $ \restore -> do
    x <- before
    res1 <- C.try $ restore (thing x)
    case res1 of
        Left (e1 :: SomeException) -> do
            -- ignore the exception, see bracket for explanation
            _ :: Either SomeException b <-
                C.try $ C.uninterruptibleMask_ $ after x
            C.throwM e1
        Right y -> return y

-- | Async safe version of 'E.bracketOnError_'
--
-- @since 0.1.0.0
bracketOnError_ :: C.MonadMask m => m a -> m b -> m c -> m c
bracketOnError_ before after thing = bracketOnError before (const after) (const thing)

-- | Wrap up an asynchronous exception to be treated as a synchronous
-- exception
--
-- This is intended to be created via 'toSyncException'
--
-- @since 0.1.0.0
data SyncExceptionWrapper = forall e. Exception e => SyncExceptionWrapper e
    deriving Typeable
instance Show SyncExceptionWrapper where
    show (SyncExceptionWrapper e) = show e
instance Exception SyncExceptionWrapper where
#if MIN_VERSION_base(4,8,0)
    displayException (SyncExceptionWrapper e) = displayException e
#endif

-- | Convert an exception into a synchronous exception
--
-- For synchronous exceptions, this is the same as 'toException'.
-- For asynchronous exceptions, this will wrap up the exception with
-- 'SyncExceptionWrapper'
--
-- @since 0.1.0.0
toSyncException :: Exception e => e -> SomeException
toSyncException e =
    case fromException se of
        Just (SomeAsyncException _) -> toException (SyncExceptionWrapper e)
        Nothing -> se
  where
    se = toException e

-- | Wrap up a synchronous exception to be treated as an asynchronous
-- exception
--
-- This is intended to be created via 'toAsyncException'
--
-- @since 0.1.0.0
data AsyncExceptionWrapper = forall e. Exception e => AsyncExceptionWrapper e
    deriving Typeable
instance Show AsyncExceptionWrapper where
    show (AsyncExceptionWrapper e) = show e
instance Exception AsyncExceptionWrapper where
    toException = toException . SomeAsyncException
    fromException se = do
        SomeAsyncException e <- fromException se
        cast e
#if MIN_VERSION_base(4,8,0)
    displayException (AsyncExceptionWrapper e) = displayException e
#endif

-- | Convert an exception into an asynchronous exception
--
-- For asynchronous exceptions, this is the same as 'toException'.
-- For synchronous exceptions, this will wrap up the exception with
-- 'AsyncExceptionWrapper'
--
-- @since 0.1.0.0
toAsyncException :: Exception e => e -> SomeException
toAsyncException e =
    case fromException se of
        Just (SomeAsyncException _) -> se
        Nothing -> toException (AsyncExceptionWrapper e)
  where
    se = toException e

-- | Check if the given exception is synchronous
--
-- @since 0.1.0.0
isSyncException :: Exception e => e -> Bool
isSyncException e =
    case fromException (toException e) of
        Just (SomeAsyncException _) -> False
        Nothing -> True

-- | Check if the given exception is asynchronous
--
-- @since 0.1.0.0
isAsyncException :: Exception e => e -> Bool
isAsyncException = not . isSyncException
{-# INLINE isAsyncException #-}

#if !MIN_VERSION_base(4,8,0)
-- | A synonym for 'show', specialized to 'Exception' instances.
--
-- Starting with base 4.8, the 'Exception' typeclass has a method @displayException@, used for user-friendly display of exceptions. This function provides backwards compatibility for users on base 4.7 and earlier, so that anyone importing this module can simply use @displayException@.
--
-- @since 0.1.1.0
displayException :: Exception e => e -> String
displayException = show
#endif
